Workbook

Sheet Deal Summary
A1: FULTON HOTEL - INVESTMENT SUMMARY
A3: Property | B3: 2208-2210 Fulton Ave, Cincinnati OH 45206
A4: Neighborhood | B4: East Walnut Hills
A5: Zoning | B5: RMX-MH (no parking min, no density limit)
A6: Building | B6: 3-story, ~12,000 SF
A7: Unit Mix | B7: 12 Standard + 4 Loft = 16 micro-suites
A8: Acquisition | B8: $0 (already owned)
A10: PROJECT COST & CAPITAL STACK
A12: Renovation Budget | B12: ='Capital Stack'!B5 -> 1625080
A13: Capitalized Interest | B13: ='Capital Stack'!B7 -> 37734.844
A14: Pre-Opening Costs | B14: ='Capital Stack'!B6 -> 53000
A15: Total Project Cost | B15: ='Capital Stack'!B8 -> 1715814.8
A17: Senior Debt (75%) | B17: ='Capital Stack'!B10 -> 1286861.1
A18: Total Equity (25%) | B18: ='Capital Stack'!B11 -> 428953.71
A19: Sponsor (30%) | B19: ='Capital Stack'!B12 -> 128686.11
A20: Investor (70%) | B20: ='Capital Stack'!B13 -> 300267.6
A22: 5-YEAR OPERATING SUMMARY
B23: Year 1 | C23: Year 2 | D23: Year 3 | E23: Year 4 | F23: Year 5
A24: Occupancy | B24: ='Operating Model'!B82 -> 0.7625 | C24: ='Operating Model'!C82 -> 0.9 | D24: ='Operating Model'!D82 -> 0.92 | E24: ='Operating Model'!E82 -> 0.92 | F24: ='Operating Model'!F82 -> 0.92
A25: Gross Revenue | B25: ='Operating Model'!B86 -> 535993.05 | C25: ='Operating Model'!C86 -> 658245.86 | D25: ='Operating Model'!D86 -> 692776.84 | E25: ='Operating Model'!E86 -> 713560.15 | F25: ='Operating Model'!F86 -> 734966.95
A26: Operating Expenses | B26: ='Operating Model'!B108 -> 343828.95 | C26: ='Operating Model'!C108 -> 369533.55 | D26: ='Operating Model'!D108 -> 382000.22 | E26: ='Operating Model'!E108 -> 392148.07 | F26: ='Operating Model'!F108 -> 402567.81
A27: NOI | B27: ='Operating Model'!B110 -> 192164.1 | C27: ='Operating Model'!C110 -> 288712.3 | D27: ='Operating Model'!D110 -> 310776.63 | E27: ='Operating Model'!E110 -> 321412.08 | F27: ='Operating Model'!F110 -> 332399.14
A28: Debt Service | B28: ='Operating Model'!B111 -> 124402.39 | C28: ='Operating Model'!C111 -> 124402.39 | D28: ='Operating Model'!D111 -> 124402.39 | E28: ='Operating Model'!E111 -> 124402.39 | F28: ='Operating Model'!F111 -> 124402.39
A29: Cash Flow Before Tax | B29: ='Operating Model'!B112 -> 67761.713 | C29: ='Operating Model'!C112 -> 164309.92 | D29: ='Operating Model'!D112 -> 186374.24 | E29: ='Operating Model'!E112 -> 197009.69 | F29: ='Operating Model'!F112 -> 207996.75
A31: Cash-on-Cash Return | B31: ='Operating Model'!B117 -> 0.15796976 | C31: ='Operating Model'!C117 -> 0.38304813 | D31: ='Operating Model'!D117 -> 0.43448567 | E31: ='Operating Model'!E117 -> 0.45927961 | F31: ='Operating Model'!F117 -> 0.48489324
A32: DSCR | B32: ='Operating Model'!B116 -> 1.5446978 | C32: ='Operating Model'!C116 -> 2.3207939 | D32: ='Operating Model'!D116 -> 2.4981564 | E32: ='Operating Model'!E116 -> 2.5836488 | F32: ='Operating Model'!F116 -> 2.6719675
A33: OER | B33: ='Operating Model'!B115 -> 0.64148024 | C33: ='Operating Model'!C115 -> 0.56139138 | D33: ='Operating Model'!D115 -> 0.55140442 | E33: ='Operating Model'!E115 -> 0.54956554 | F33: ='Operating Model'!F115 -> 0.54773593
A35: KEY HIGHLIGHTS
A36: Construction Period | B36: 9 months
A37: Monthly P&I | B37: ='Capital Stack'!B17 -> 10366.866
A38: Breakeven Occupancy | B38: =('Operating Model'!B108+'Operating Model'!B111)/('Operating Model'!B86/'Operating Model'!B82) -> 0.66610266
A39: Investor Preferred Return (annual) | B39: ='Capital Stack'!B24 -> 24021.408
A40: Simple Payback (years) | B40: ='Capital Stack'!B11/'Operating Model'!B112 -> 6.3303257

Sheet Project Timeline
A1: PROJECT TIMELINE - CONSTRUCTION THROUGH YEAR 1
B3: Mo 1 | C3: Mo 2 | D3: Mo 3 | E3: Mo 4 | F3: Mo 5 | G3: Mo 6 | H3: Mo 7 | I3: Mo 8 | J3: Mo 9 | K3: Mo 10 | L3: Mo 11 | M3: Mo 12 | N3: Mo 13 | O3: Mo 14 | P3: Mo 15 | Q3: Mo 16 | R3: Mo 17 | S3: Mo 18 | T3: Mo 19 | U3: Mo 20 | V3: Mo 21 | W3: TOTAL
B4: (Const) | C4: (Const) | D4: (Const) | E4: (Const) | F4: (Const) | G4: (Const) | H4: (Const) | I4: (Const) | J4: (Const) | K4: (Ops 1) | L4: (Ops 2) | M4: (Ops 3) | N4: (Ops 4) | O4: (Ops 5) | P4: (Ops 6) | Q4: (Ops 7) | R4: (Ops 8) | S4: (Ops 9) | T4: (Ops 10) | U4: (Ops 11) | V4: (Ops 12)
A6: RENOVATION DRAW SCHEDULE
A7: Unit Renovations | B7: ='Renovation Budget'!E9*0.1 -> 61600 | C7: ='Renovation Budget'!E9*0.1 -> 61600 | D7: ='Renovation Budget'!E9*0.15 -> 92400 | E7: ='Renovation Budget'!E9*0.15 -> 92400 | F7: ='Renovation Budget'!E9*0.15 -> 92400 | G7: ='Renovation Budget'!E9*0.15 -> 92400 | H7: ='Renovation Budget'!E9*0.1 -> 61600 | I7: ='Renovation Budget'!E9*0.1 -> 61600 | J7: 0 | K7: 0 | L7: 0 | M7: 0 | N7: 0 | O7: 0 | P7: 0 | Q7: 0 | R7: 0 | S7: 0 | T7: 0 | U7: 0 | V7: 0 | W7: =SUM(B7:V7) -> 616000
A8: Common Areas | B8: ='Renovation Budget'!E17*0.05 -> 15750 | C8: ='Renovation Budget'!E17*0.05 -> 15750 | D8: ='Renovation Budget'!E17*0.1 -> 31500 | E8: ='Renovation Budget'!E17*0.1 -> 31500 | F8: ='Renovation Budget'!E17*0.1 -> 31500 | G8: ='Renovation Budget'!E17*0.2 -> 63000 | H8: ='Renovation Budget'!E17*0.2 -> 63000 | I8: ='Renovation Budget'!E17*0.15 -> 47250 | J8: ='Renovation Budget'!E17*0.05 -> 15750 | K8: 0 | L8: 0 | M8: 0 | N8: 0 | O8: 0 | P8: 0 | Q8: 0 | R8: 0 | S8: 0 | T8: 0 | U8: 0 | V8: 0 | W8: =SUM(B8:V8) -> 315000
A9: Building Systems | B9: ='Renovation Budget'!E26*0.2 -> 64000 | C9: ='Renovation Budget'!E26*0.2 -> 64000 | D9: ='Renovation Budget'!E26*0.15 -> 48000 | E9: ='Renovation Budget'!E26*0.15 -> 48000 | F9: ='Renovation Budget'!E26*0.1 -> 32000 | G9: ='Renovation Budget'!E26*0.1 -> 32000 | H9: ='Renovation Budget'!E26*0.1 -> 32000 | I9: 0 | J9: 0 | K9: 0 | L9: 0 | M9: 0 | N9: 0 | O9: 0 | P9: 0 | Q9: 0 | R9: 0 | S9: 0 | T9: 0 | U9: 0 | V9: 0 | W9: =SUM(B9:V9) -> 320000
A10: Exterior | B10: 0 | C10: 0 | D10: 0 | E10: 0 | F10: 0 | G10: ='Renovation Budget'!E33*0.2 -> 21000 | H10: ='Renovation Budget'!E33*0.2 -> 21000 | I10: ='Renovation Budget'!E33*0.3 -> 31500 | J10: ='Renovation Budget'!E33*0.3 -> 31500 | K10: 0 | L10: 0 | M10: 0 | N10: 0 | O10: 0 | P10: 0 | Q10: 0 | R10: 0 | S10: 0 | T10: 0 | U10: 0 | V10: 0 | W10: =SUM(B10:V10) -> 105000
A11: Soft Costs | B11: ='Renovation Budget'!E41/9 -> 14831.111 | C11: ='Renovation Budget'!E41/9 -> 14831.111 | D11: ='Renovation Budget'!E41/9 -> 14831.111 | E11: ='Renovation Budget'!E41/9 -> 14831.111 | F11: ='Renovation Budget'!E41/9 -> 14831.111 | G11: ='Renovation Budget'!E41/9 -> 14831.111 | H11: ='Renovation Budget'!E41/9 -> 14831.111 | I11: ='Renovation Budget'!E41/9 -> 14831.111 | J11: ='Renovation Budget'!E41/9 -> 14831.111 | K11: 0 | L11: 0 | M11: 0 | N11: 0 | O11: 0 | P11: 0 | Q11: 0 | R11: 0 | S11: 0 | T11: 0 | U11: 0 | V11: 0 | W11: =SUM(B11:V11) -> 133480
A12: Contingency | B12: 0 | C12: 0 | D12: 0 | E12: 0 | F12: 0 | G12: 0 | H12: ='Renovation Budget'!E43*0.3 -> 40680 | I12: ='Renovation Budget'!E43*0.4 -> 54240 | J12: ='Renovation Budget'!E43*0.3 -> 40680 | K12: 0 | L12: 0 | M12: 0 | N12: 0 | O12: 0 | P12: 0 | Q12: 0 | R12: 0 | S12: 0 | T12: 0 | U12: 0 | V12: 0 | W12: =SUM(B12:V12) -> 135600
A13: MONTHLY DRAW TOTAL | B13: =SUM(B7:B12) -> 156181.11 | C13: =SUM(C7:C12) -> 156181.11 | D13: =SUM(D7:D12) -> 186731.11 | E13: =SUM(E7:E12) -> 186731.11 | F13: =SUM(F7:F12) -> 170731.11 | G13: =SUM(G7:G12) -> 223231.11 | H13: =SUM(H7:H12) -> 233111.11 | I13: =SUM(I7:I12) -> 209421.11 | ... V13: =SUM(V7:V12) -> 0 | W13: =SUM(B13:V13) -> 1625080
A14: CUMULATIVE DRAWS | B14: =B13 -> 156181.11 | C14: =B14+C13 -> 312362.22 | D14: =C14+D13 -> 499093.33 | E14: =D14+E13 -> 685824.44 | F14: =E14+F13 -> 856555.56 | G14: =F14+G13 -> 1079786.7 | H14: =G14+H13 -> 1312897.8 | I14: =H14+I13 -> 1522318.9 | J14: =I14+J13 -> 1625080 | ... V14: =U14+V13 -> 1625080 | W14: =V14 -> 1625080
A16: INTEREST CARRY
A17: Drawn Loan Balance (75%) | B17: =B14*'Operating Model'!B66 -> 117135.83 | C17: =C14*'Operating Model'!B66 -> 234271.67 | D17: =D14*'Operating Model'!B66 -> 374320 | E17: =E14*'Operating Model'!B66 -> 514368.33 | F17: =F14*'Operating Model'!B66 -> 642416.67 | G17: =G14*'Operating Model'!B66 -> 809840 | H17: =H14*'Operating Model'!B66 -> 984673.33 | I17: =I14*'Operating Model'!B66 -> 1141739.2 | J17: =J14*'Operating Model'!B66 -> 1218810 | K17: 0 | L17: 0 | M17: 0 | N17: 0 | O17: 0 | P17: 0 | Q17: 0 | R17: 0 | S17: 0 | T17: 0 | U17: 0 | V17: 0 | W17: =J17 -> 1218810
A18: Monthly Interest | B18: =B17*'Operating Model'!B63/12 -> 732.09896 | C18: =C17*'Operating Model'!B63/12 -> 1464.1979 | D18: =D17*'Operating Model'!B63/12 -> 2339.5 | E18: =E17*'Operating Model'!B63/12 -> 3214.8021 | F18: =F17*'Operating Model'!B63/12 -> 4015.1042 | G18: =G17*'Operating Model'!B63/12 -> 5061.5 | H18: =H17*'Operating Model'!B63/12 -> 6154.2083 | I18: =I17*'Operating Model'!B63/12 -> 7135.8698 | J18: =J17*'Operating Model'!B63/12 -> 7617.5625 | K18: 0 | L18: 0 | M18: 0 | N18: 0 | O18: 0 | P18: 0 | Q18: 0 | R18: 0 | S18: 0 | T18: 0 | U18: 0 | V18: 0 | W18: =SUM(B18:V18) -> 37734.844
A19: CUMULATIVE INTEREST | B19: =B18 -> 732.09896 | C19: =B19+C18 -> 2196.2969 | D19: =C19+D18 -> 4535.7969 | E19: =D19+E18 -> 7750.599 | F19: =E19+F18 -> 11765.703 | G19: =F19+G18 -> 16827.203 | H19: =G19+H18 -> 22981.411 | I19: =H19+I18 -> 30117.281 | J19: =I19+J18 -> 37734.844 | K19: 0 | L19: 0 | M19: 0 | N19: 0 | O19: 0 | P19: 0 | Q19: 0 | R19: 0 | S19: 0 | T19: 0 | U19: 0 | V19: 0 | W19: =J19 -> 37734.844
A21: PRE-OPENING COSTS
A22: Staff Hiring & Training | B22: 0 | C22: 0 | D22: 0 | E22: 0 | F22: 0 | G22: 0 | H22: 0 | I22: 3200 | J22: 6400 | K22: 6400 | L22: 0 | M22: 0 | N22: 0 | O22: 0 | P22: 0 | Q22: 0 | R22: 0 | S22: 0 | T22: 0 | U22: 0 | V22: 0 | W22: =SUM(B22:V22) -> 16000
A23: Marketing & Website | B23: 0 | C23: 0 | D23: 0 | E23: 0 | F23: 0 | G23: 0 | H23: 2000 | I23: 3000 | J23: 2500 | K23: 2500 | L23: 0 | M23: 0 | N23: 0 | O23: 0 | P23: 0 | Q23: 0 | R23: 0 | S23: 0 | T23: 0 | U23: 0 | V23: 0 | W23: =SUM(B23:V23) -> 10000
A24: OTA Setup & Photography | B24: 0 | C24: 0 | D24: 0 | E24: 0 | F24: 0 | G24: 0 | H24: 0 | I24: 0 | J24: 3000 | K24: 2000 | L24: 0 | M24: 0 | N24: 0 | O24: 0 | P24: 0 | Q24: 0 | R24: 0 | S24: 0 | T24: 0 | U24: 0 | V24: 0 | W24: =SUM(B24:V24) -> 5000
A25: Initial Inventory | B25: 0 | C25: 0 | D25: 0 | E25: 0 | F25: 0 | G25: 0 | H25: 0 | I25: 0 | J25: 8000 | K25: 12000 | L25: 0 | M25: 0 | N25: 0 | O25: 0 | P25: 0 | Q25: 0 | R25: 0 | S25: 0 | T25: 0 | U25: 0 | V25: 0 | W25: =SUM(B25:V25) -> 20000
A26: Licensing & Permits | B26: 2000 | C26: 0 | D26: 0 | E26: 0 | F26: 0 | G26: 0 | H26: 0 | I26: 0 | J26: 0 | K26: 0 | L26: 0 | M26: 0 | N26: 0 | O26: 0 | P26: 0 | Q26: 0 | R26: 0 | S26: 0 | T26: 0 | U26: 0 | V26: 0 | W26: =SUM(B26:V26) -> 2000
A27: MONTHLY PRE-OPENING | B27: =SUM(B22:B26) -> 2000 | C27: =SUM(C22:C26) -> 0 | D27: =SUM(D22:D26) -> 0 | E27: =SUM(E22:E26) -> 0 | F27: =SUM(F22:F26) -> 0 | G27: =SUM(G22:G26) -> 0 | H27: =SUM(H22:H26) -> 2000 | I27: =SUM(I22:I26) -> 6200 | ... V27: =SUM(V22:V26) -> 0 | W27: =SUM(B27:V27) -> 53000
A28: CUMULATIVE PRE-OPENING | B28: =B27 -> 2000 | C28: =B28+C27 -> 2000 | D28: =C28+D27 -> 2000 | E28: =D28+E27 -> 2000 | F28: =E28+F27 -> 2000 | G28: =F28+G27 -> 2000 | H28: =G28+H27 -> 4000 | I28: =H28+I27 -> 10200 | J28: =I28+J27 -> 30100 | ... V28: =U28+V27 -> 53000 | W28: =V28 -> 53000
A30: PROJECT CASH FLOW
A31: SOURCES
A32: Loan Draws | B32: =SUM(B38:B40)*'Operating Model'!B66 -> 119184.91 | C32: =SUM(C38:C40)*'Operating Model'!B66 -> 118233.98 | D32: =SUM(D38:D40)*'Operating Model'!B66 -> 141802.96 | E32: =SUM(E38:E40)*'Operating Model'!B66 -> 142459.43 | F32: =SUM(F38:F40)*'Operating Model'!B66 -> 131059.66 | G32: =SUM(G38:G40)*'Operating Model'!B66 -> 171219.46 | H32: =SUM(H38:H40)*'Operating Model'!B66 -> 180948.99 | I32: =SUM(I38:I40)*'Operating Model'!B66 -> 167067.74 | J32: =SUM(J38:J40)*'Operating Model'!B66 -> 97709.005 | K32: =SUM(K38:K40)*'Operating Model'!B66 -> 17175 | L32: =SUM(L38:L40)*'Operating Model'!B66 -> 0 | M32: =SUM(M38:M40)*'Operating Model'!B66 -> 0 | N32: =SUM(N38:N40)*'Operating Model'!B66 -> 0 | O32: =SUM(O38:O40)*'Operating Model'!B66 -> 0 | P32: =SUM(P38:P40)*'Operating Model'!B66 -> 0 | Q32: =SUM(Q38:Q40)*'Operating Model'!B66 -> 0 | R32: =SUM(R38:R40)*'Operating Model'!B66 -> 0 | S32: =SUM(S38:S40)*'Operating Model'!B66 -> 0 | T32: =SUM(T38:T40)*'Operating Model'!B66 -> 0 | U32: =SUM(U38:U40)*'Operating Model'!B66 -> 0 | V32: =SUM(V38:V40)*'Operating Model'!B66 -> 0 | W32: =SUM(B32:V32) -> 1286861.1
A33: Equity Deployed | B33: =SUM(B38:B40)-B32 -> 39728.303 | C33: =SUM(C38:C40)-C32 -> 39411.327 | D33: =SUM(D38:D40)-D32 -> 47267.653 | E33: =SUM(E38:E40)-E32 -> 47486.478 | F33: =SUM(F38:F40)-F32 -> 43686.554 | G33: =SUM(G38:G40)-G32 -> 57073.153 | H33: =SUM(H38:H40)-H32 -> 60316.33 | I33: =SUM(I38:I40)-I32 -> 55689.245 | ... V33: =SUM(V38:V40)-V32 -> 0 | W33: =SUM(B33:V33) -> 428953.71
A34: Operating Revenue | B34: 0 | C34: 0 | D34: 0 | E34: 0 | F34: 0 | G34: 0 | H34: 0 | I34: 0 | J34: 0 | K34: ='Operating Model'!B78 -> 35360.2 | L34: ='Operating Model'!C78 -> 35360.2 | M34: ='Operating Model'!D78 -> 35360.2 | N34: ='Operating Model'!E78 -> 43950.25 | O34: ='Operating Model'!F78 -> 43950.25 | P34: ='Operating Model'!G78 -> 43950.25 | Q34: ='Operating Model'!H78 -> 49676.95 | R34: ='Operating Model'!I78 -> 49676.95 | ... V34: ='Operating Model'!M78 -> 49676.95 | W34: =SUM(B34:V34) -> 535993.05
A35: TOTAL INFLOWS | B35: =B32+B33+B34 -> 158913.21 | C35: =C32+C33+C34 -> 157645.31 | D35: =D32+D33+D34 -> 189070.61 | E35: =E32+E33+E34 -> 189945.91 | F35: =F32+F33+F34 -> 174746.22 | G35: =G32+G33+G34 -> 228292.61 | H35: =H32+H33+H34 -> 241265.32 | I35: =I32+I33+I34 -> 222756.98 | ... V35: =V32+V33+V34 -> 49676.95 | W35: =SUM(B35:V35) -> 2251807.9
A37: USES
A38: Renovation Spending | B38: =B13 -> 156181.11 | C38: =C13 -> 156181.11 | D38: =D13 -> 186731.11 | E38: =E13 -> 186731.11 | F38: =F13 -> 170731.11 | G38: =G13 -> 223231.11 | H38: =H13 -> 233111.11 | I38: =I13 -> 209421.11 | J38: =J13 -> 102761.11 | K38: 0 | L38: 0 | M38: 0 | N38: 0 | O38: 0 | P38: 0 | Q38: 0 | R38: 0 | S38: 0 | T38: 0 | U38: 0 | V38: 0 | W38: =SUM(B38:V38) -> 1625080
A39: Interest Carry | B39: =B18 -> 732.09896 | C39: =C18 -> 1464.1979 | D39: =D18 -> 2339.5 | E39: =E18 -> 3214.8021 | F39: =F18 -> 4015.1042 | G39: =G18 -> 5061.5 | H39: =H18 -> 6154.2083 | I39: =I18 -> 7135.8698 | J39: =J18 -> 7617.5625 | K39: 0 | L39: 0 | M39: 0 | N39: 0 | O39: 0 | P39: 0 | Q39: 0 | R39: 0 | S39: 0 | T39: 0 | U39: 0 | V39: 0 | W39: =SUM(B39:V39) -> 37734.844
A40: Pre-Opening Costs | B40: =B27 -> 2000 | C40: =C27 -> 0 | D40: =D27 -> 0 | E40: =E27 -> 0 | F40: =F27 -> 0 | G40: =G27 -> 0 | H40: =H27 -> 2000 | I40: =I27 -> 6200 | ... V40: =V27 -> 0 | W40: =SUM(B40:V40) -> 53000
A41: Operating Expenses | B41: 0 | C41: 0 | D41: 0 | E41: 0 | F41: 0 | G41: 0 | H41: 0 | I41: 0 | J41: 0 | K41: ='Operating Model'!B139 -> 26977.353 | L41: ='Operating Model'!C139 -> 26977.353 | M41: ='Operating Model'!D139 -> 26977.353 | N41: ='Operating Model'!E139 -> 28523.562 | O41: ='Operating Model'!F139 -> 28523.562 | P41: ='Operating Model'!G139 -> 28523.562 | Q41: ='Operating Model'!H139 -> 29554.368 | R41: ='Operating Model'!I139 -> 29554.368 | ... V41: ='Operating Model'!M139 -> 29554.368 | W41: =SUM(B41:V41) -> 343828.95
A42: Debt Service (P&I) | B42: 0 | C42: 0 | D42: 0 | E42: 0 | F42: 0 | G42: 0 | H42: 0 | I42: 0 | J42: 0 | K42: ='Capital Stack'!B17 -> 10366.866 | L42: ='Capital Stack'!B17 -> 10366.866 | M42: ='Capital Stack'!B17 -> 10366.866 | N42: ='Capital Stack'!B17 -> 10366.866 | O42: ='Capital Stack'!B17 -> 10366.866 | P42: ='Capital Stack'!B17 -> 10366.866 | Q42: ='Capital Stack'!B17 -> 10366.866 | R42: ='Capital Stack'!B17 -> 10366.866 | S42: ='Capital Stack'!B17 -> 10366.866 | T42: ='Capital Stack'!B17 -> 10366.866 | U42: ='Capital Stack'!B17 -> 10366.866 | V42: ='Capital Stack'!B17 -> 10366.866 | W42: =SUM(B42:V42) -> 124402.39
A43: TOTAL OUTFLOWS | B43: =SUM(B38:B42) -> 158913.21 | C43: =SUM(C38:C42) -> 157645.31 | D43: =SUM(D38:D42) -> 189070.61 | E43: =SUM(E38:E42) -> 189945.91 | F43: =SUM(F38:F42) -> 174746.22 | G43: =SUM(G38:G42) -> 228292.61 | H43: =SUM(H38:H42) -> 241265.32 | I43: =SUM(I38:I42) -> 222756.98 | ... V43: =SUM(V38:V42) -> 39921.233 | W43: =SUM(B43:V43) -> 2184046.2
A45: NET MONTHLY CASH FLOW | B45: =B35-B43 -> 0 | C45: =C35-C43 -> 0 | D45: =D35-D43 -> 0 | E45: =E35-E43 -> 0 | F45: =F35-F43 -> 0 | G45: =G35-G43 -> 0 | H45: =H35-H43 -> 0 | I45: =I35-I43 -> 0 | ... V45: =V35-V43 -> 9755.7166 | W45: =SUM(B45:V45) -> 67761.713
A46: CUMULATIVE CASH FLOW | B46: =B45 -> 0 | C46: =B46+C45 -> 0 | D46: =C46+D45 -> 0 | E46: =D46+E45 -> 0 | F46: =E46+F45 -> 0 | G46: =F46+G45 -> 0 | H46: =G46+H45 -> 0 | I46: =H46+I45 -> 0 | J46: =I46+J45 -> 0 | ... V46: =U46+V45 -> 67761.713 | W46: =V46 -> 67761.713
A47: CUMULATIVE EQUITY DEPLOYED | B47: =B33 -> 39728.303 | C47: =B47+C33 -> 79139.63 | D47: =C47+D33 -> 126407.28 | E47: =D47+E33 -> 173893.76 | F47: =E47+F33 -> 217580.31 | G47: =F47+G33 -> 274653.47 | H47: =G47+H33 -> 334969.8 | I47: =H47+I33 -> 390659.04 | J47: =I47+J33 -> 423228.71 | ... V47: =U47+V33 -> 428953.71 | W47: =V47 -> 428953.71
...

Sheet Capital Stack
A1: CAPITAL STACK & INVESTOR RETURNS
A3: CAPITAL STRUCTURE
A4: Source | B4: Amount | C4: % of Total | D4: Terms
A5: Renovation Budget | B5: ='Renovation Budget'!E45 -> 1625080
A6: Pre-Opening Costs | B6: ='Project Timeline'!B52 -> 53000
A7: Capitalized Interest | B7: ='Project Timeline'!B51 -> 37734.844
A8: TOTAL PROJECT COST | B8: =SUM(B5:B7) -> 1715814.8
A10: Senior Debt | B10: =B8*'Operating Model'!B66 -> 1286861.1 | C10: =B10/B8 -> 0.75 | D10: 7.5%, 20yr amort, 5yr term
A11: Total Equity | B11: =B8-B10 -> 428953.71 | C11: =B11/B8 -> 0.25
A12: Sponsor Equity | B12: =B11*'Operating Model'!B67 -> 128686.11 | C12: =B12/B8 -> 0.075
A13: Investor Equity | B13: =B11*'Operating Model'!B68 -> 300267.6 | C13: =B13/B8 -> 0.175
A14: TOTAL CAPITALIZATION | B14: =B10+B11 -> 1715814.8 | C14: =B14/B8 -> 1
A16: DEBT SERVICE
A17: Monthly P&I | B17: =PMT('Operating Model'!B63/12,'Operating Model'!B64*12,-B10) -> 10366.866
A18: Annual Debt Service | B18: =B17*12 -> 124402.39
A19: Loan Maturity | B19: Month 60 (Year 5)
A21: INVESTOR CASH FLOW WATERFALL
B22: Year 1 | C22: Year 2 | D22: Year 3 | E22: Year 4 | F22: Year 5
A23: Cash Flow Before Tax | B23: ='Operating Model'!B112 -> 67761.713 | C23: ='Operating Model'!C112 -> 164309.92 | D23: ='Operating Model'!D112 -> 186374.24 | E23: ='Operating Model'!E112 -> 197009.69 | F23: ='Operating Model'!F112 -> 207996.75
A24: Preferred Return (8%) | B24: =B13*'Operating Model'!B69 -> 24021.408 | C24: =B13*'Operating Model'!B69 -> 24021.408 | D24: =B13*'Operating Model'!B69 -> 24021.408 | E24: =B13*'Operating Model'!B69 -> 24021.408 | F24: =B13*'Operating Model'!B69 -> 24021.408
A25: Remaining After Preferred | B25: =B23-B24 -> 43740.305 | C25: =C23-C24 -> 140288.51 | D25: =D23-D24 -> 162352.83 | E25: =E23-E24 -> 172988.28 | F25: =F23-F24 -> 183975.35
A26: Investor Share (70%) | B26: =B25*'Operating Model'!B68 -> 30618.213 | C26: =C25*'Operating Model'!B68 -> 98201.956 | D26: =D25*'Operating Model'!B68 -> 113646.98 | E26: =E25*'Operating Model'!B68 -> 121091.8 | F26: =F25*'Operating Model'!B68 -> 128782.74
A27: Sponsor Share (30%) | B27: =B25*'Operating Model'!B67 -> 13122.091 | C27: =C25*'Operating Model'!B67 -> 42086.553 | D27: =D25*'Operating Model'!B67 -> 48705.85 | E27: =E25*'Operating Model'!B67 -> 51896.485 | F27: =F25*'Operating Model'!B67 -> 55192.604
A28: Total to Investor | B28: =B24+B26 -> 54639.621 | C28: =C24+C26 -> 122223.36 | D28: =D24+D26 -> 137668.39 | E28: =E24+E26 -> 145113.21 | F28: =F24+F26 -> 152804.15
A29: Total to Sponsor | B29: =B27 -> 13122.091 | C29: =C27 -> 42086.553 | D29: =D27 -> 48705.85 | E29: =E27 -> 51896.485 | F29: =F27 -> 55192.604
A31: INVESTOR METRICS
A32: Cumulative to Investor | B32: =B28 -> 54639.621 | C32: =B32+C28 -> 176862.99 | D32: =C32+D28 -> 314531.38 | E32: =D32+E28 -> 459644.58 | F32: =E32+F28 -> 612448.73
A33: Investor Equity Multiple | B33: =B32/B13 -> 0.18196976 | C33: =C32/B13 -> 0.58901788 | D33: =D32/B13 -> 1.0475036 | E33: =E32/B13 -> 1.5307832 | F33: =F32/B13 -> 2.0396764
A34: Investor Cash-on-Cash | B34: =B28/B13 -> 0.18196976 | C34: =C28/B13 -> 0.40704813 | D34: =D28/B13 -> 0.45848567 | E34: =E28/B13 -> 0.48327961 | F34: =F28/B13 -> 0.50889324
A35: Sponsor Cash-on-Cash | B35: =B29/B12 -> 0.10196976 | C35: =C29/B12 -> 0.32704813 | D35: =D29/B12 -> 0.37848567 | E35: =E29/B12 -> 0.40327961 | F35: =F29/B12 -> 0.42889324

Sheet Renovation Budget
A1: RENOVATION BUDGET
A3: Category | B3: Description | C3: Quantity | D3: Unit Cost | E3: Total
A5: UNIT RENOVATIONS
A6: Standard Room Renovation | C6: 12 | D6: 30000 | E6: =C6*D6 -> 360000
A7: Loft Suite Conversion | C7: 4 | D7: 60000 | E7: =C7*D7 -> 240000
A8: ADA Compliance | C8: 2 | D8: 8000 | E8: =C8*D8 -> 16000
A9: Subtotal Units | E9: =SUM(E6:E8) -> 616000
A11: COMMON AREAS
A12: Lobby Renovation | E12: 75000
A13: Hallway Updates | E13: 40000
A14: Front Porch | E14: 25000
A15: Basement Lounge | E15: 115000
A16: Rooftop Deck (OPTIONAL) | E16: 60000
A17: Subtotal Common | E17: =SUM(E12:E16) -> 315000
A19: BUILDING SYSTEMS
A20: HVAC | E20: 120000
A21: Electrical | E21: 65000
A22: Plumbing | E22: 55000
A23: Fire Safety | E23: 40000
A24: Security System | E24: 15000
A25: WiFi Infrastructure | E25: 25000
A26: Subtotal Systems | E26: =SUM(E20:E25) -> 320000
A28: EXTERIOR
A29: Facade Restoration | E29: 45000
A30: Parking Lot | E30: 30000
A31: Signage | E31: 15000
A32: Exterior Lighting | E32: 15000
A33: Subtotal Exterior | E33: =SUM(E29:E32) -> 105000
A35: TOTAL HARD COSTS | E35: =E9+E17+E26+E33 -> 1356000
A37: SOFT COSTS
A38: Architecture & Engineering (8%) | E38: =E35*0.08 -> 108480
A39: Permits & Fees | E39: 15000
A40: Legal | E40: 10000
A41: Total Soft Costs | E41: =SUM(E38:E40) -> 133480
A43: Contingency (10% of hard) | E43: =E35*0.1 -> 135600
A45: TOTAL RENOVATION BUDGET | E45: =E35+E41+E43 -> 1625080
A46: Per-Unit Cost | E46: =E45/'Operating Model'!B8 -> 101567.5

Sheet Operating Model
A1: OPERATING MODEL
A3: SECTION A: KEY ASSUMPTIONS
A5: Property | B5: Fulton Hotel, 2208-2210 Fulton Ave
A6: Standard Rooms | B6: 12
A7: Loft Suites | B7: 4
A8: Total Units | B8: =B6+B7 -> 16
A9: Building SF | B9: 12000
A11: RATE STRUCTURE
A12: Standard Nightly Rate | B12: 139
A13: Loft Nightly Rate | B13: 189
A14: Weekly Discount | B14: 0.15
A15: Monthly Discount | B15: 0.35
A16: Stay Mix - Nightly | B16: 0.25
A17: Stay Mix - Weekly | B17: 0.25
A18: Stay Mix - Monthly | B18: =1-B16-B17 -> 0.5
A19: Blended Std Nightly | B19: =B12*(B16*1+B17*(1-B14)+B18*(1-B15)) -> 109.4625
A20: Blended Loft Nightly | B20: =B13*(B16*1+B17*(1-B14)+B18*(1-B15)) -> 148.8375
A22: OCCUPANCY RAMP
A23: Ops Months 1-3 | B23: 0.6
A24: Ops Months 4-6 | B24: 0.75
A25: Ops Months 7-12 | B25: 0.85
A26: Year 2 | B26: 0.9
A27: Year 3+ (Stabilized) | B27: 0.92
A28: Year 1 Avg Occupancy | B28: =(B23*3+B24*3+B25*6)/12 -> 0.7625
A30: GROWTH RATES
A31: Revenue Growth | B31: 0.03
A32: Expense Growth | B32: 0.025
A33: Property Tax Growth | B33: 0.02
A35: OPERATING EXPENSES (per unit/month)
A36: Utilities | B36: 150
A37: Insurance | B37: 75
A38: Maintenance | B38: 100
A39: Cleaning/Turnover | B39: 300
A40: Supplies | B40: 50
A41: WiFi/Tech | B41: 40
A42: Total Per-Unit Monthly | B42: =SUM(B36:B41) -> 715
A44: REVENUE-BASED FEES
A45: Management Fee % | B45: 0.08
A46: Platform/Booking Fee % | B46: 0.05
A47: Replacement Reserves % | B47: 0.05
...

Sheet Validation
A1: VALIDATION CHECKS
A2: Invariant-based checks for the live workbook model
A4: Test | B4: Expected | C4: Actual | D4: Status
A5: Project Cost = Reno + Interest + PreOpen | B5: ='Capital Stack'!B5+'Capital Stack'!B6+'Capital Stack'!B7 -> 1715814.8 | C5: ='Capital Stack'!B8 -> 1715814.8 | D5: =IF(ABS(B5-C5)<1,"PASS","FAIL") -> PASS
A6: Loan = 75% of Project Cost | B6: ='Capital Stack'!B8*0.75 -> 1286861.1 | C6: ='Capital Stack'!B10 -> 1286861.1 | D6: =IF(ABS(B6-C6)<1,"PASS","FAIL") -> PASS
A7: Equity = Project Cost - Loan | B7: ='Capital Stack'!B8-'Capital Stack'!B10 -> 428953.71 | C7: ='Capital Stack'!B11 -> 428953.71 | D7: =IF(ABS(B7-C7)<1,"PASS","FAIL") -> PASS
A8: Sponsor + Investor = Total Equity | B8: ='Capital Stack'!B12+'Capital Stack'!B13 -> 428953.71 | C8: ='Capital Stack'!B11 -> 428953.71 | D8: =IF(ABS(B8-C8)<1,"PASS","FAIL") -> PASS
A9: Annual Debt Service = Monthly x 12 | B9: ='Capital Stack'!B17*12 -> 124402.39 | C9: ='Capital Stack'!B18 -> 124402.39 | D9: =IF(ABS(B9-C9)<1,"PASS","FAIL") -> PASS
A10: Year 1 NOI = Revenue - OpEx | B10: ='Operating Model'!B90-'Operating Model'!B108 -> 192164.1 | C10: ='Operating Model'!B110 -> 192164.1 | D10: =IF(ABS(B10-C10)<1,"PASS","FAIL") -> PASS
A11: Year 1 CFBT = NOI - Debt Service | B11: ='Operating Model'!B110-'Operating Model'!B111 -> 67761.713 | C11: ='Operating Model'!B112 -> 67761.713 | D11: =IF(ABS(B11-C11)<1,"PASS","FAIL") -> PASS
A12: Year 1 DSCR = NOI / Debt Service | B12: ='Operating Model'!B110/'Operating Model'!B111 -> 1.5446978 | C12: ='Operating Model'!B116 -> 1.5446978 | D12: =IF(ABS(B12-C12)<0.01,"PASS","FAIL") -> PASS
A13: Cash-on-Cash = CFBT / Equity | B13: ='Operating Model'!B112/'Capital Stack'!B11 -> 0.15796976 | C13: ='Operating Model'!B117 -> 0.15796976 | D13: =IF(ABS(B13-C13)<0.01,"PASS","FAIL") -> PASS
A14: Waterfall: Pref + InvShare + SponShare = CFBT | B14: ='Capital Stack'!B24+'Capital Stack'!B26+'Capital Stack'!B27 -> 67761.713 | C14: ='Capital Stack'!B23 -> 67761.713 | D14: =IF(ABS(B14-C14)<1,"PASS","FAIL") -> PASS
A15: Year 1 Revenue (annual) = Sum of Monthly | B15: ='Operating Model'!N78 -> 535993.05 | C15: ='Operating Model'!B86 -> 535993.05 | D15: =IF(ABS(B15-C15)<1,"PASS","FAIL") -> PASS
A16: Year 1 Monthly CF Sum = Annual CFBT | B16: ='Operating Model'!N143 -> 67761.713 | C16: ='Operating Model'!B112 -> 67761.713 | D16: =IF(ABS(B16-C16)<1,"PASS","FAIL") -> PASS
A17: Timeline Renovation Spend = Renovation Budget | B17: ='Project Timeline'!B50 -> 1625080 | C17: ='Renovation Budget'!E45 -> 1625080 | D17: =IF(ABS(B17-C17)<1,"PASS","FAIL") -> PASS
A18: Timeline Debt Funding = Senior Debt | B18: ='Project Timeline'!W32 -> 1286861.1 | C18: ='Capital Stack'!B10 -> 1286861.1 | D18: =IF(ABS(B18-C18)<1,"PASS","FAIL") -> PASS
A19: Timeline Equity Funding = Total Equity | B19: ='Project Timeline'!W33 -> 428953.71 | C19: ='Capital Stack'!B11 -> 428953.71 | D19: =IF(ABS(B19-C19)<1,"PASS","FAIL") -> PASS
A20: Timeline Net = Inflows - Outflows | B20: ='Project Timeline'!W35-'Project Timeline'!W43 -> 67761.713 | C20: ='Project Timeline'!W45 -> 67761.713 | D20: =IF(ABS(B20-C20)<1,"PASS","FAIL") -> PASS
A21: Breakeven Occupancy < Stabilized Occupancy | B21: ='Operating Model'!B27 -> 0.92 | C21: ='Deal Summary'!B38 -> 0.66610266 | D21: =IF(C21<B21,"PASS","FAIL") -> PASS
A22: TOTAL TESTS PASSING | D22: =COUNTIF(D5:D21,"PASS")&" / "&ROWS(D5:D21) -> 17 / 17
